Exception in download_nist_data: HTTPSConnectionPool(host='nvd.nist.gov', port=443): Max retries exceeded with url: /feeds/json/cve/1.1/nvdcve-1.1-2020.json.gz (Caused by NewConnectionError('<urllib3.connection.HTTPSConnection object at 0x7f123cdb6770>: Failed to establish a new connection: [Errno 111] Connection refused'))
Error retrieving NIST data {nist_data}
Exception in download_nist_data: HTTPSConnectionPool(host='nvd.nist.gov', port=443): Max retries exceeded with url: /feeds/json/cve/1.1/nvdcve-1.1-2021.json.gz (Caused by ConnectTimeoutError(<urllib3.connection.HTTPSConnection object at 0x7f123cdb5960>, 'Connection to nvd.nist.gov timed out. (connect timeout=None)'))
Error retrieving NIST data {nist_data}
Exception in download_nist_data: HTTPSConnectionPool(host='nvd.nist.gov', port=443): Max retries exceeded with url: /feeds/json/cve/1.1/nvdcve-1.1-2022.json.gz (Caused by NewConnectionError('<urllib3.connection.HTTPSConnection object at 0x7f123cdb5780>: Failed to establish a new connection: [Errno 111] Connection refused'))
Error retrieving NIST data {nist_data}
Exception in download_nist_data: HTTPSConnectionPool(host='nvd.nist.gov', port=443): Max retries exceeded with url: /feeds/json/cve/1.1/nvdcve-1.1-2023.json.gz (Caused by ConnectTimeoutError(<urllib3.connection.HTTPSConnection object at 0x7f123cdb7310>, 'Connection to nvd.nist.gov timed out. (connect timeout=None)'))
Error retrieving NIST data {nist_data}
